2019-05-21 08:53:31 WARNING (MainThread) [homeassistant.loader] You are using a custom integration for circadian_lighting which has not been tested by Home Assistant. This component might cause stability problems, be sure to disable it if you do experience issues with Home Assistant.
2019-05-21 08:53:41 WARNING (MainThread) [homeassistant.loader] You are using a custom integration for google_geocode which has not been tested by Home Assistant. This component might cause stability problems, be sure to disable it if you do experience issues with Home Assistant.
2019-05-21 08:53:42 WARNING (MainThread) [homeassistant.loader] You are using a custom integration for postnl which has not been tested by Home Assistant. This component might cause stability problems, be sure to disable it if you do experience issues with Home Assistant.
2019-05-21 08:53:47 WARNING (MainThread) [homeassistant.setup] Setup of xiaomi_aqara is taking over 10 seconds.
2019-05-21 08:53:59 ERROR (SyncWorker_4) [homeassistant.components.qnap.sensor] Failed to fetch QNAP stats from the NAS
Traceback (most recent call last):
  File "/srv/digitijn/lib/python3.6/site-packages/urllib3/connectionpool.py", line 384, in _make_request
    six.raise_from(e, None)
  File "<string>", line 2, in raise_from
  File "/srv/digitijn/lib/python3.6/site-packages/urllib3/connectionpool.py", line 380, in _make_request
    httplib_response = conn.getresponse()
  File "/usr/lib/python3.6/http/client.py", line 1331, in getresponse
    response.begin()
  File "/usr/lib/python3.6/http/client.py", line 297, in begin
    version, status, reason = self._read_status()
  File "/usr/lib/python3.6/http/client.py", line 258, in _read_status
    line = str(self.fp.readline(_MAXLINE + 1), "iso-8859-1")
  File "/usr/lib/python3.6/socket.py", line 586, in readinto
    return self._sock.recv_into(b)
socket.timeout: timed out

During handling of the above exception, another exception occurred:

Traceback (most recent call last):
  File "/srv/digitijn/lib/python3.6/site-packages/requests/adapters.py", line 449, in send
    timeout=timeout
  File "/srv/digitijn/lib/python3.6/site-packages/urllib3/connectionpool.py", line 638, in urlopen
    _stacktrace=sys.exc_info()[2])
  File "/srv/digitijn/lib/python3.6/site-packages/urllib3/util/retry.py", line 367, in increment
    raise six.reraise(type(error), error, _stacktrace)
  File "/srv/digitijn/lib/python3.6/site-packages/urllib3/packages/six.py", line 686, in reraise
    raise value
  File "/srv/digitijn/lib/python3.6/site-packages/urllib3/connectionpool.py", line 600, in urlopen
    chunked=chunked)
  File "/srv/digitijn/lib/python3.6/site-packages/urllib3/connectionpool.py", line 386, in _make_request
    self._raise_timeout(err=e, url=url, timeout_value=read_timeout)
  File "/srv/digitijn/lib/python3.6/site-packages/urllib3/connectionpool.py", line 306, in _raise_timeout
    raise ReadTimeoutError(self, url, "Read timed out. (read timeout=%s)" % timeout_value)
urllib3.exceptions.ReadTimeoutError: HTTPConnectionPool(host='10.0.1.101', port=8080): Read timed out. (read timeout=5)

During handling of the above exception, another exception occurred:

Traceback (most recent call last):
  File "/srv/digitijn/lib/python3.6/site-packages/homeassistant/components/qnap/sensor.py", line 180, in update
    self.data["system_health"] = self._api.get_system_health()
  File "/srv/digitijn/lib/python3.6/site-packages/qnapstats/qnap_stats.py", line 121, in get_system_health
    resp = self._get_url("management/manaRequest.cgi?subfunc=sysinfo&sysHealth=1")
  File "/srv/digitijn/lib/python3.6/site-packages/qnapstats/qnap_stats.py", line 69, in _get_url
    result = self._execute_get_url(url, **kwargs)
  File "/srv/digitijn/lib/python3.6/site-packages/qnapstats/qnap_stats.py", line 85, in _execute_get_url
    resp = self._session.get(url, timeout=self._timeout, verify=self._verify_ssl)
  File "/srv/digitijn/lib/python3.6/site-packages/requests/sessions.py", line 546, in get
    return self.request('GET', url, **kwargs)
  File "/srv/digitijn/lib/python3.6/site-packages/requests/sessions.py", line 533, in request
    resp = self.send(prep, **send_kwargs)
  File "/srv/digitijn/lib/python3.6/site-packages/requests/sessions.py", line 646, in send
    r = adapter.send(request, **kwargs)
  File "/srv/digitijn/lib/python3.6/site-packages/requests/adapters.py", line 529, in send
    raise ReadTimeout(e, request=request)
requests.exceptions.ReadTimeout: HTTPConnectionPool(host='10.0.1.101', port=8080): Read timed out. (read timeout=5)
2019-05-21 08:54:00 ERROR (MainThread) [homeassistant.components.sensor] Error while setting up platform qnap
Traceback (most recent call last):
  File "/srv/digitijn/lib/python3.6/site-packages/homeassistant/helpers/entity_platform.py", line 126, in _async_setup_platform
    SLOW_SETUP_MAX_WAIT, loop=hass.loop)
  File "/usr/lib/python3.6/asyncio/tasks.py", line 358, in wait_for
    return fut.result()
  File "/usr/lib/python3.6/concurrent/futures/thread.py", line 56, in run
    result = self.fn(*self.args, **self.kwargs)
  File "/srv/digitijn/lib/python3.6/site-packages/homeassistant/components/qnap/sensor.py", line 130, in setup_platform
    for drive in config.get(CONF_DRIVES, api.data["smart_drive_health"]):
KeyError: 'smart_drive_health'
2019-05-21 08:54:01 ERROR (SyncWorker_12) [homeassistant.components.waze_travel_time.sensor] Error on retrieving data: empty response
2019-05-21 08:54:04 ERROR (SyncWorker_9) [homeassistant.components.waze_travel_time.sensor] Error on retrieving data: empty response
2019-05-21 08:54:30 WARNING (MainThread) [homeassistant.helpers.service] Unable to find services.yaml for the circadian_lighting integration
2019-05-21 08:54:34 ERROR (SyncWorker_11) [homeassistant.util.yaml] YAML file /home/digitijn/.homeassistant/ui-lovelace.yaml contains duplicate key "type". Check lines 1026 and 1036.
2019-05-21 08:54:34 ERROR (SyncWorker_11) [homeassistant.util.yaml] YAML file /home/digitijn/.homeassistant/ui-lovelace.yaml contains duplicate key "type". Check lines 1057 and 1067.
2019-05-21 08:54:34 ERROR (SyncWorker_11) [homeassistant.util.yaml] YAML file /home/digitijn/.homeassistant/ui-lovelace.yaml contains duplicate key "type". Check lines 1088 and 1098.
2019-05-21 08:54:34 ERROR (SyncWorker_11) [homeassistant.util.yaml] YAML file /home/digitijn/.homeassistant/ui-lovelace.yaml contains duplicate key "type". Check lines 1119 and 1129.
2019-05-21 08:54:34 ERROR (SyncWorker_11) [homeassistant.util.yaml] YAML file /home/digitijn/.homeassistant/ui-lovelace.yaml contains duplicate key "type". Check lines 1238 and 1248.
2019-05-21 08:54:34 ERROR (SyncWorker_11) [homeassistant.util.yaml] YAML file /home/digitijn/.homeassistant/ui-lovelace.yaml contains duplicate key "type". Check lines 1269 and 1279.
2019-05-21 08:54:34 ERROR (SyncWorker_11) [homeassistant.util.yaml] YAML file /home/digitijn/.homeassistant/ui-lovelace.yaml contains duplicate key "type". Check lines 1300 and 1310.
2019-05-21 08:54:34 ERROR (SyncWorker_11) [homeassistant.util.yaml] YAML file /home/digitijn/.homeassistant/ui-lovelace.yaml contains duplicate key "type". Check lines 1397 and 1407.
2019-05-21 08:54:34 ERROR (SyncWorker_11) [homeassistant.util.yaml] YAML file /home/digitijn/.homeassistant/ui-lovelace.yaml contains duplicate key "type". Check lines 1428 and 1438.
2019-05-21 08:54:34 ERROR (SyncWorker_11) [homeassistant.util.yaml] YAML file /home/digitijn/.homeassistant/ui-lovelace.yaml contains duplicate key "type". Check lines 1459 and 1469.
2019-05-21 08:54:34 ERROR (SyncWorker_11) [homeassistant.util.yaml] YAML file /home/digitijn/.homeassistant/ui-lovelace.yaml contains duplicate key "type". Check lines 1490 and 1500.
2019-05-21 08:54:34 ERROR (SyncWorker_11) [homeassistant.util.yaml] YAML file /home/digitijn/.homeassistant/ui-lovelace.yaml contains duplicate key "type". Check lines 1521 and 1531.
2019-05-21 08:54:34 ERROR (SyncWorker_11) [homeassistant.util.yaml] YAML file /home/digitijn/.homeassistant/ui-lovelace.yaml contains duplicate key "type". Check lines 1612 and 1622.
2019-05-21 08:54:34 ERROR (SyncWorker_11) [homeassistant.util.yaml] YAML file /home/digitijn/.homeassistant/ui-lovelace.yaml contains duplicate key "type". Check lines 1643 and 1653.
2019-05-21 08:54:34 ERROR (SyncWorker_11) [homeassistant.util.yaml] YAML file /home/digitijn/.homeassistant/ui-lovelace.yaml contains duplicate key "type". Check lines 1674 and 1684.
2019-05-21 08:54:34 ERROR (SyncWorker_11) [homeassistant.util.yaml] YAML file /home/digitijn/.homeassistant/ui-lovelace.yaml contains duplicate key "type". Check lines 1705 and 1715.
